#VRML_SIM R2023a utf8

EXTERNPROTO "https://raw.githubusercontent.com/cyberbotics/webots/R2023a/projects/objects/backgrounds/protos/TexturedBackground.proto"
EXTERNPROTO "https://raw.githubusercontent.com/cyberbotics/webots/R2023a/projects/objects/backgrounds/protos/TexturedBackgroundLight.proto"
EXTERNPROTO "https://raw.githubusercontent.com/cyberbotics/webots/R2023a/projects/objects/floors/protos/Floor.proto"
EXTERNPROTO "https://raw.githubusercontent.com/cyberbotics/webots/R2023a/projects/objects/balls/protos/Ball.proto"

WorldInfo {
  ERP 0.7
  basicTimeStep 16
  contactProperties [
    ContactProperties {
      material2 "dumbbell"
    }
  ]
}
Viewpoint {
  orientation -0.2615138878797314 0.6003438688809399 0.7557762403933402 1.0457266730532297
  position -1.777225405578783 -3.5509195911838654 3.5196164702592756
}
TexturedBackground {
}
TexturedBackgroundLight {
}
Floor {
  size 20 20
}
DEF Blue Robot {
  translation 0.5623768383185123 -0.0648932594599804 0.3846689980979289
  rotation 0.002152211150184966 -0.1501211862270752 0.9886652605573542 0.009057829653497206
  children [
    InertialUnit {
      noise 0.0001
    }
    DEF lidar_location Transform {
      translation 0.44 0 0.65
      children [
        Shape {
          appearance Appearance {
            material Material {
              diffuseColor 0.333333 0.341176 0.32549
            }
          }
          geometry Cylinder {
            height 0.08
            radius 0.05
          }
        }
      ]
    }
    Solid {
      translation 0.44 0 0.31
      rotation 0 1 0 0
      children [
        Shape {
          appearance Appearance {
            material Material {
              diffuseColor 0.203922 0.396078 0.643137
            }
          }
          geometry Cylinder {
            height 0.6
            radius 0.02
          }
        }
      ]
      name "lidar beam"
    }
    Transform {
      translation -0.24 -0.4 -0.205
      rotation 0 0 1 1.5707996938995747
      scale 0.32 0.32 0.3
      children [
        DEF RIGHT_REAR_WHEEL_HINGE HingeJoint {
          jointParameters HingeJointParameters {
            position 2.433979583662189
            dampingConstant 5
            suspensionAxis 0 0 1
          }
          device [
            RotationalMotor {
              name "right_rear_wheel"
              acceleration 2.314814814814815
              maxVelocity 83.33333333333334
              maxTorque 100000000
              sound ""
            }
            PositionSensor {
              name "right_rear_sensor"
            }
            Brake {
              name "right_rear_brake"
            }
          ]
          endPoint Slot {
            type "vehicle wheel"
            endPoint Slot {
              type "vehicle wheel"
              endPoint Solid {
                rotation 1 0 0 0.4371067301076433
                children [
                  Transform {
                    translation 0.05 0 0
                    rotation 0 1 0 1.5708
                    children [
                      Shape {
                        appearance PBRAppearance {
                          baseColorMap ImageTexture {
                            url [
                              "https://raw.githubusercontent.com/cyberbotics/webots/R2023a/projects/vehicles/protos/generic/textures/tractor_tire_tread_base_color.jpg"
                            ]
                          }
                          roughness 0.4
                          metalness 0
                          normalMap ImageTexture {
                            url [
                              "https://raw.githubusercontent.com/cyberbotics/webots/R2023a/projects/vehicles/protos/generic/textures/tractor_tire_tread_normal.jpg"
                            ]
                          }
                          occlusionMap ImageTexture {
                            url [
                              "https://raw.githubusercontent.com/cyberbotics/webots/R2023a/projects/vehicles/protos/generic/textures/tractor_tire_tread_occlusion.jpg"
                            ]
                          }
                          textureTransform TextureTransform {
                            rotation 1.5708
                            scale 1 7
                          }
                        }
                        geometry Cylinder {
                          bottom FALSE
                          height 0.37
                          radius 0.6
                          top FALSE
                          subdivision 24
                        }
                      }
                      Shape {
                        appearance PBRAppearance {
                          baseColorMap ImageTexture {
                            url [
                              "https://raw.githubusercontent.com/cyberbotics/webots/R2023a/projects/vehicles/protos/generic/textures/tractor_rear_tire_side_base_color.jpg"
                            ]
                          }
                          roughnessMap ImageTexture {
                            url [
                              "https://raw.githubusercontent.com/cyberbotics/webots/R2023a/projects/vehicles/protos/generic/textures/tractor_rear_tire_side_roughness.jpg"
                            ]
                          }
                          metalnessMap ImageTexture {
                            url [
                              "https://raw.githubusercontent.com/cyberbotics/webots/R2023a/projects/vehicles/protos/generic/textures/tractor_rear_tire_side_metalness.jpg"
                            ]
                          }
                          normalMap ImageTexture {
                            url [
                              "https://raw.githubusercontent.com/cyberbotics/webots/R2023a/projects/vehicles/protos/generic/textures/tractor_rear_tire_side_normal.jpg"
                            ]
                          }
                          occlusionMap ImageTexture {
                            url [
                              "https://raw.githubusercontent.com/cyberbotics/webots/R2023a/projects/vehicles/protos/generic/textures/tractor_rear_tire_side_occlusion.jpg"
                            ]
                          }
                        }
                        geometry Cylinder {
                          height 0.37
                          radius 0.6
                          side FALSE
                          subdivision 24
                        }
                      }
                    ]
                  }
                ]
                name "rear right wheel"
                model "tractor rear wheel"
                boundingObject Group {
                  children [
                    Transform {
                      translation 0.04 0 0
                      rotation 0 1 0 1.5708
                      children [
                        Cylinder {
                          height 0.37
                          radius 0.6
                          subdivision 60
                        }
                      ]
                    }
                  ]
                }
                physics Physics {
                  density -1
                  mass 30
                }
                linearVelocity 1.320465860133962e-09 -1.8589545059899114e-11 2.316014159882525e-15
                angularVelocity -4.220466016640209e-12 4.721458058133519e-10 5.672954156007273e-11
              }
            }
          }
        }
      ]
    }
    Transform {
      translation -0.24 0.39 -0.205
      rotation 0 0 1 -1.5708
      scale 0.32 0.32 0.3
      children [
        DEF LEFT_REAR_WHEEL_HINGE HingeJoint {
          jointParameters HingeJointParameters {
            position 9.20728739979798
            axis -1 0 0
            dampingConstant 5
            suspensionAxis 0 0 1
          }
          device [
            RotationalMotor {
              name "left_rear_wheel"
              acceleration 2.314814814814815
              maxVelocity 83.33333333333334
              maxTorque 100000000
              sound ""
            }
            PositionSensor {
              name "left_rear_sensor"
            }
            Brake {
              name "left_rear_brake"
            }
          ]
          endPoint Slot {
            type "vehicle wheel"
            endPoint Slot {
              type "vehicle wheel"
              endPoint Solid {
                rotation -1 0 0 0.43645110913625523
                children [
                  Transform {
                    translation 0.05 0 0
                    rotation 0 -1 0 1.5708
                    children [
                      Shape {
                        appearance PBRAppearance {
                          baseColorMap ImageTexture {
                            url [
                              "https://raw.githubusercontent.com/cyberbotics/webots/R2023a/projects/vehicles/protos/generic/textures/tractor_tire_tread_base_color.jpg"
                            ]
                          }
                          roughness 0.4
                          metalness 0
                          normalMap ImageTexture {
                            url [
                              "https://raw.githubusercontent.com/cyberbotics/webots/R2023a/projects/vehicles/protos/generic/textures/tractor_tire_tread_normal.jpg"
                            ]
                          }
                          occlusionMap ImageTexture {
                            url [
                              "https://raw.githubusercontent.com/cyberbotics/webots/R2023a/projects/vehicles/protos/generic/textures/tractor_tire_tread_occlusion.jpg"
                            ]
                          }
                          textureTransform TextureTransform {
                            rotation 1.5708
                            scale 1 7
                          }
                        }
                        geometry Cylinder {
                          bottom FALSE
                          height 0.37
                          radius 0.6
                          top FALSE
                          subdivision 24
                        }
                      }
                      Shape {
                        appearance PBRAppearance {
                          baseColorMap ImageTexture {
                            url [
                              "https://raw.githubusercontent.com/cyberbotics/webots/R2023a/projects/vehicles/protos/generic/textures/tractor_rear_tire_side_base_color.jpg"
                            ]
                          }
                          roughnessMap ImageTexture {
                            url [
                              "https://raw.githubusercontent.com/cyberbotics/webots/R2023a/projects/vehicles/protos/generic/textures/tractor_rear_tire_side_roughness.jpg"
                            ]
                          }
                          metalnessMap ImageTexture {
                            url [
                              "https://raw.githubusercontent.com/cyberbotics/webots/R2023a/projects/vehicles/protos/generic/textures/tractor_rear_tire_side_metalness.jpg"
                            ]
                          }
                          normalMap ImageTexture {
                            url [
                              "https://raw.githubusercontent.com/cyberbotics/webots/R2023a/projects/vehicles/protos/generic/textures/tractor_rear_tire_side_normal.jpg"
                            ]
                          }
                          occlusionMap ImageTexture {
                            url [
                              "https://raw.githubusercontent.com/cyberbotics/webots/R2023a/projects/vehicles/protos/generic/textures/tractor_rear_tire_side_occlusion.jpg"
                            ]
                          }
                        }
                        geometry Cylinder {
                          height 0.37
                          radius 0.6
                          side FALSE
                          subdivision 24
                        }
                      }
                    ]
                  }
                ]
                name "rear left wheel"
                model "tractor rear wheel"
                boundingObject Group {
                  children [
                    Transform {
                      translation 0.04 0 0
                      rotation 0 1 0 1.5708
                      children [
                        Cylinder {
                          height 0.37
                          radius 0.6
                          subdivision 60
                        }
                      ]
                    }
                  ]
                }
                physics Physics {
                  density -1
                  mass 30
                }
                linearVelocity 1.2771105229927901e-09 -1.8976431264071707e-11 -1.9839394869393125e-15
                angularVelocity -4.095587621226646e-12 4.566471633048276e-10 5.672835697524482e-11
              }
            }
          }
        }
      ]
    }
    Transform {
      translation 0.835 0.35 -0.24
      rotation 0 0 1 -1.5708
      scale 0.4 0.4 0.4
      children [
        DEF LEFT_STEER_HINGE2 Hinge2Joint {
          jointParameters HingeJointParameters {
            position -3.216149283731743e-09
            axis 0 0 -1
            dampingConstant 5
            suspensionAxis 0 0 1
          }
          jointParameters2 JointParameters {
            position 23.259588221017246
            axis -1 0 0
            dampingConstant 5
          }
          device [
            RotationalMotor {
              name "left_steer"
              minPosition -0.45
              maxPosition 0.45
              maxTorque 10000
              sound ""
            }
            PositionSensor {
              name "left_steer_sensor"
            }
          ]
          device2 [
            RotationalMotor {
              name "left_front_wheel"
              acceleration 3.654970760233918
              maxVelocity 131.57894736842104
              maxTorque 0
              sound ""
            }
            PositionSensor {
              name "left_front_sensor"
            }
            Brake {
              name "left_front_brake"
            }
          ]
          endPoint Slot {
            type "vehicle wheel"
            endPoint Slot {
              type "vehicle wheel"
              endPoint Solid {
                rotation -0.9999999988409852 -7.484645308897098e-06 -4.75605913006596e-05 0.3120491870056506
                children [
                  Transform {
                    translation 0.041 0 0
                    rotation 0 -1 0 1.5708
                    children [
                      Shape {
                        appearance PBRAppearance {
                          baseColorMap ImageTexture {
                            url [
                              "https://raw.githubusercontent.com/cyberbotics/webots/R2023a/projects/vehicles/protos/generic/textures/tractor_tire_tread_base_color.jpg"
                            ]
                          }
                          roughness 0.4
                          metalness 0
                          normalMap ImageTexture {
                            url [
                              "https://raw.githubusercontent.com/cyberbotics/webots/R2023a/projects/vehicles/protos/generic/textures/tractor_tire_tread_normal.jpg"
                            ]
                          }
                          occlusionMap ImageTexture {
                            url [
                              "https://raw.githubusercontent.com/cyberbotics/webots/R2023a/projects/vehicles/protos/generic/textures/tractor_tire_tread_occlusion.jpg"
                            ]
                          }
                          textureTransform TextureTransform {
                            rotation 1.5708
                            scale 1 7
                          }
                        }
                        geometry Cylinder {
                          bottom FALSE
                          height 0.19
                          radius 0.38
                          top FALSE
                          subdivision 24
                        }
                      }
                      Shape {
                        appearance PBRAppearance {
                          baseColorMap ImageTexture {
                            url [
                              "https://raw.githubusercontent.com/cyberbotics/webots/R2023a/projects/vehicles/protos/generic/textures/tractor_front_tire_side_base_color.jpg"
                            ]
                          }
                          roughnessMap ImageTexture {
                            url [
                              "https://raw.githubusercontent.com/cyberbotics/webots/R2023a/projects/vehicles/protos/generic/textures/tractor_front_tire_side_roughness.jpg"
                            ]
                          }
                          normalMap ImageTexture {
                            url [
                              "https://raw.githubusercontent.com/cyberbotics/webots/R2023a/projects/vehicles/protos/generic/textures/tractor_front_tire_side_normal.jpg"
                            ]
                          }
                          occlusionMap ImageTexture {
                            url [
                              "https://raw.githubusercontent.com/cyberbotics/webots/R2023a/projects/vehicles/protos/generic/textures/tractor_front_tire_side_occlusion.jpg"
                            ]
                          }
                        }
                        geometry Cylinder {
                          height 0.19
                          radius 0.38
                          side FALSE
                          subdivision 24
                        }
                      }
                    ]
                  }
                ]
                name "front left wheel"
                model "tractor front wheel"
                boundingObject Group {
                  children [
                    Transform {
                      translation 0.04 0 0
                      rotation 0 1 0 1.5708
                      children [
                        Cylinder {
                          height 0.19
                          radius 0.38
                          subdivision 60
                        }
                      ]
                    }
                  ]
                }
                physics Physics {
                  density -1
                  mass 10
                }
                linearVelocity 1.2790181806203046e-09 4.2018006341741056e-11 -3.3764535998988244e-16
                angularVelocity -1.405359699264725e-10 1.5701020801260864e-08 5.69254514286674e-11
              }
            }
          }
        }
      ]
    }
    Transform {
      translation 0.835 -0.36 -0.24
      rotation 0 0 1 1.5708
      scale 0.4 0.4 0.4
      children [
        DEF RIGHT_STEER_HINGE2 Hinge2Joint {
          jointParameters HingeJointParameters {
            position 3.221402522306087e-09
            axis 0 0 -1
            dampingConstant 5
            suspensionAxis 0 0 1
          }
          jointParameters2 JointParameters {
            position 20.979591421894316
            axis 1 0 0
            dampingConstant 5
          }
          device [
            RotationalMotor {
              name "right_steer"
              minPosition -0.45
              maxPosition 0.45
              maxTorque 10000
              sound ""
            }
            PositionSensor {
              name "right_steer_sensor"
            }
          ]
          device2 [
            RotationalMotor {
              name "right_front_wheel"
              acceleration 3.654970760233918
              maxVelocity 131.57894736842104
              maxTorque 0
              sound ""
            }
            PositionSensor {
              name "right_front_sensor"
            }
          ]
          endPoint Slot {
            type "vehicle wheel"
            endPoint Slot {
              type "vehicle wheel"
              endPoint Solid {
                rotation 0.9999999977939369 -8.995763676919702e-06 6.581187272274299e-05 0.27159828362140626
                children [
                  Transform {
                    translation 0.041 0 0
                    rotation 0 1 0 1.5708
                    children [
                      Shape {
                        appearance PBRAppearance {
                          baseColorMap ImageTexture {
                            url [
                              "https://raw.githubusercontent.com/cyberbotics/webots/R2023a/projects/vehicles/protos/generic/textures/tractor_tire_tread_base_color.jpg"
                            ]
                          }
                          roughness 0.4
                          metalness 0
                          normalMap ImageTexture {
                            url [
                              "https://raw.githubusercontent.com/cyberbotics/webots/R2023a/projects/vehicles/protos/generic/textures/tractor_tire_tread_normal.jpg"
                            ]
                          }
                          occlusionMap ImageTexture {
                            url [
                              "https://raw.githubusercontent.com/cyberbotics/webots/R2023a/projects/vehicles/protos/generic/textures/tractor_tire_tread_occlusion.jpg"
                            ]
                          }
                          textureTransform TextureTransform {
                            rotation 1.5708
                            scale 1 7
                          }
                        }
                        geometry Cylinder {
                          bottom FALSE
                          height 0.19
                          radius 0.38
                          top FALSE
                          subdivision 24
                        }
                      }
                      Shape {
                        appearance PBRAppearance {
                          baseColorMap ImageTexture {
                            url [
                              "https://raw.githubusercontent.com/cyberbotics/webots/R2023a/projects/vehicles/protos/generic/textures/tractor_front_tire_side_base_color.jpg"
                            ]
                          }
                          roughnessMap ImageTexture {
                            url [
                              "https://raw.githubusercontent.com/cyberbotics/webots/R2023a/projects/vehicles/protos/generic/textures/tractor_front_tire_side_roughness.jpg"
                            ]
                          }
                          normalMap ImageTexture {
                            url [
                              "https://raw.githubusercontent.com/cyberbotics/webots/R2023a/projects/vehicles/protos/generic/textures/tractor_front_tire_side_normal.jpg"
                            ]
                          }
                          occlusionMap ImageTexture {
                            url [
                              "https://raw.githubusercontent.com/cyberbotics/webots/R2023a/projects/vehicles/protos/generic/textures/tractor_front_tire_side_occlusion.jpg"
                            ]
                          }
                        }
                        geometry Cylinder {
                          height 0.19
                          radius 0.38
                          side FALSE
                          subdivision 24
                        }
                      }
                    ]
                  }
                ]
                name "front right wheel"
                model "tractor front wheel"
                boundingObject Group {
                  children [
                    Transform {
                      translation 0.04 0 0
                      rotation 0 1 0 1.5708
                      children [
                        Cylinder {
                          height 0.19
                          radius 0.38
                          subdivision 60
                        }
                      ]
                    }
                  ]
                }
                physics Physics {
                  density -1
                  mass 10
                }
                linearVelocity 1.3174824613896031e-09 4.2363505031104185e-11 1.0732538095963171e-15
                angularVelocity -1.5716538174353324e-10 1.7543790243530328e-08 5.69664233596184e-11
              }
            }
          }
        }
      ]
    }
    Solid {
      translation -0.24 -0.01 -0.406
      scale 0.001 0.001 0.001
      children [
        Shape {
          appearance Appearance {
            material Material {
              diffuseColor 0.933333 0.933333 0.92549
            }
          }
          geometry Mesh {
            url [
              "../stl/eje_trasero.stl"
            ]
          }
        }
      ]
      name "rear axis"
    }
    Solid {
      translation 0.83 9.38564e-08 -0.39
      rotation 1 0 0 4.692820414042842e-06
      scale 0.001 0.001 0.001
      children [
        Shape {
          appearance Appearance {
            material Material {
              diffuseColor 0.933333 0.933333 0.92549
            }
          }
          geometry Mesh {
            url [
              "../stl/eje_delantero.stl"
            ]
          }
        }
      ]
      name "frontal axis"
    }
    DEF Body Group {
      children [
        Transform {
          translation 0.831 -0.01 -0.2168
          rotation 0 1 0 0
          children [
            Shape {
              appearance Appearance {
                material Material {
                  diffuseColor 0.12549 0.290196 0.529412
                }
              }
              geometry Box {
                size 0.119 0.5 0.15
              }
            }
          ]
        }
        Transform {
          translation 0.5952 -0.002 -0.0782133
          rotation 0 1 0 0.785398
          children [
            Shape {
              appearance Appearance {
                material Material {
                  diffuseColor 0.12549 0.290196 0.529412
                }
              }
              geometry Box {
                size 0.04 0.23 0.23
              }
            }
          ]
        }
        Transform {
          translation 0.128 -0.002 -0.09
          rotation 0 1 0 0
          children [
            Shape {
              appearance Appearance {
                material Material {
                  diffuseColor 0.12549 0.290196 0.529412
                }
              }
              geometry Box {
                size 0.8 0.229 0.17
              }
            }
          ]
        }
        Transform {
          translation 0.656 -0.01 -0.223
          rotation 0 1 0 0
          children [
            Shape {
              appearance Appearance {
                material Material {
                  diffuseColor 0.12549 0.290196 0.529412
                }
              }
              geometry Box {
                size 0.236 0.1 0.15
              }
            }
          ]
        }
        Transform {
          translation 0.48 0.1873 0
          rotation 0 0 1 -0.7854003061004253
          children [
            Shape {
              appearance Appearance {
                material Material {
                  diffuseColor 0.12549 0.290196 0.529412
                }
              }
              geometry Box {
                size 0.4 0.2 0.02
              }
            }
          ]
        }
        Transform {
          translation 0.48 -0.1885 0
          rotation 0 0 1 0.7853996938995746
          children [
            Shape {
              appearance Appearance {
                material Material {
                  diffuseColor 0.12549 0.290196 0.529412
                }
              }
              geometry Box {
                size 0.4 0.2 0.02
              }
            }
          ]
        }
        Transform {
          translation 0.546 -0.001 0
          rotation 0 0 1 1.5707996938995747
          children [
            Shape {
              appearance Appearance {
                material Material {
                  diffuseColor 0.12549 0.290196 0.529412
                }
              }
              geometry Box {
                size 0.24 0.29 0.02
              }
            }
          ]
        }
        Transform {
          translation -0.307 -0.01 -0.1569
          children [
            Shape {
              appearance Appearance {
                material Material {
                  diffuseColor 0.12549 0.290196 0.529412
                }
              }
              geometry Box {
                size 0.12 0.5 0.29
              }
            }
          ]
        }
        Transform {
          translation -0.25 -0.00999996 -0.22
          rotation 1 0 0 1.5708
          children [
            Shape {
              appearance Appearance {
                material Material {
                  diffuseColor 0.12549 0.290196 0.529412
                }
              }
              geometry Cylinder {
                height 0.5
                radius 0.08
              }
            }
          ]
        }
        Transform {
          translation 0.51 -0.01 -0.17
          rotation 1 0 0 1.5708
          children [
            Shape {
              appearance Appearance {
                material Material {
                  diffuseColor 0.12549 0.290196 0.529412
                }
              }
              geometry Cylinder {
                height 0.1
                radius 0.08
              }
            }
          ]
        }
        Shape {
          appearance Appearance {
            material Material {
              diffuseColor 0.12549 0.290196 0.529412
            }
          }
          geometry Box {
            size 0.82 0.8 0.022
          }
        }
      ]
    }
    Solid {
      translation -0.25 0 -0.41
      scale 0.001 0.001 0.001
      children [
        Shape {
          appearance Appearance {
            material Material {
              diffuseColor 0.12549 0.290196 0.529412
            }
          }
          geometry Mesh {
            url [
              "../stl/base.stl"
            ]
          }
        }
      ]
      name "solid(4)"
    }
  ]
  name "Blue"
  model "Aurova"
  boundingObject Group {
    children [
      Transform {
        translation 0.831 -0.01 -0.2168
        rotation 0 1 0 0
        children [
          Shape {
            appearance Appearance {
              material Material {
                diffuseColor 0.12549 0.290196 0.529412
              }
            }
            geometry Box {
              size 0.119 0.5 0.15
            }
          }
        ]
      }
      Transform {
        translation 0.656 -0.01 -0.223
        rotation 0 1 0 0
        children [
          Shape {
            appearance Appearance {
              material Material {
                diffuseColor 0.12549 0.290196 0.529412
              }
            }
            geometry Box {
              size 0.236 0.1 0.15
            }
          }
        ]
      }
      Shape {
        appearance Appearance {
          material Material {
            diffuseColor 0.12549 0.290196 0.529412
          }
        }
        geometry Box {
          size 0.82 0.8 0.022
        }
      }
      Transform {
        translation 0.51 -0.01 -0.17
        rotation 1 0 0 1.5708
        children [
          Shape {
            appearance Appearance {
              material Material {
                diffuseColor 0.12549 0.290196 0.529412
              }
            }
            geometry Cylinder {
              height 0.1
              radius 0.08
            }
          }
        ]
      }
      Transform {
        translation -0.25 -0.00999996 -0.22
        rotation 1 0 0 1.5708
        children [
          Shape {
            appearance Appearance {
              material Material {
                diffuseColor 0.12549 0.290196 0.529412
              }
            }
            geometry Cylinder {
              height 0.5
              radius 0.08
            }
          }
        ]
      }
      Transform {
        translation -0.307 -0.01 -0.1569
        children [
          Shape {
            appearance Appearance {
              material Material {
                diffuseColor 0.12549 0.290196 0.529412
              }
            }
            geometry Box {
              size 0.12 0.5 0.29
            }
          }
        ]
      }
      Transform {
        translation 0.546 -0.001 0
        rotation 0 0 1 1.5707996938995747
        children [
          Shape {
            appearance Appearance {
              material Material {
                diffuseColor 0.12549 0.290196 0.529412
              }
            }
            geometry Box {
              size 0.24 0.29 0.02
            }
          }
        ]
      }
      Transform {
        translation 0.48 -0.1885 0
        rotation 0 0 1 0.7853996938995746
        children [
          Shape {
            appearance Appearance {
              material Material {
                diffuseColor 0.12549 0.290196 0.529412
              }
            }
            geometry Box {
              size 0.4 0.2 0.02
            }
          }
        ]
      }
      Transform {
        translation 0.48 0.1873 0
        rotation 0 0 1 -0.7854003061004253
        children [
          Shape {
            appearance Appearance {
              material Material {
                diffuseColor 0.12549 0.290196 0.529412
              }
            }
            geometry Box {
              size 0.4 0.2 0.02
            }
          }
        ]
      }
      Transform {
        translation 0.128 -0.002 -0.09
        rotation 0 1 0 0
        children [
          Shape {
            appearance Appearance {
              material Material {
                diffuseColor 0.12549 0.290196 0.529412
              }
            }
            geometry Box {
              size 0.8 0.229 0.17
            }
          }
        ]
      }
      Transform {
        translation 0.5952 -0.002 -0.0782133
        rotation 0 1 0 0.785398
        children [
          Shape {
            appearance Appearance {
              material Material {
                diffuseColor 0.12549 0.290196 0.529412
              }
            }
            geometry Box {
              size 0.04 0.23 0.23
            }
          }
        ]
      }
    ]
  }
  physics Physics {
    density -1
    mass 92.31471578978483
    centerOfMass [
      0.11093156408503682 -0.005191642674491525 -0.11650620364377519
    ]
    inertiaMatrix [
      3.907230066027804 17.546992814010718 17.29635552123587
      0.04126603977304788 1.3618277649651465 -0.08601659987551691
    ]
  }
  controller "<extern>"
  supervisor TRUE
  linearVelocity 1.29861991401027e-09 1.113374001591118e-12 -2.3053936568411685e-15
  angularVelocity 2.041160263315058e-15 5.635218200132905e-15 5.6721355504304567e-11
}
Ball {
  translation 0.6589140224071313 -0.6312148941518613 0.03245683600000001
  rotation -1.314024666654966e-13 -3.242010621472495e-13 -1 1.1626964291316326
}
